<robot name = "robot">
    <link name="000">
        <inertial>
            <origin xyz="0.0 0.0 0.25" rpy="0 0 0"/>
            <mass value="1" />
            <inertia ixx="100" ixy="0" ixz="0" iyy="100" iyz="0" izz="100" />
        </inertial>
        <visual>
            <origin xyz="0.0 0.0 0.25" rpy="0 0 0"/>
            <geometry>
                <box size="0.5 0.5 0.5" />
            </geometry>
            <material name="Green">
                <color rgba="0.4 1 0.4 1"/>
            </material>
        </visual>
        <collision>
            <origin xyz="0.0 0.0 0.25" rpy="0 0 0"/>
            <geometry>
                <box size="0.5 0.5 0.5" />
            </geometry>
        </collision>
    </link>
    <joint name="000_001" type="revolute">
       <parent link="000"/>
       <child  link="001"/>
       <origin rpy="0 0 0" xyz="0.0 0.0 0.5" />
     <axis xyz="0 1 0"/>
       <limit effort="0.0" lower="-3.14159" upper="3.14159" velocity="0.0"/>
    </joint>
    <link name="001">
        <inertial>
            <origin xyz="0.0 0.0 0.25" rpy="0 0 0"/>
            <mass value="1" />
            <inertia ixx="100" ixy="0" ixz="0" iyy="100" iyz="0" izz="100" />
        </inertial>
        <visual>
            <origin xyz="0.0 0.0 0.25" rpy="0 0 0"/>
            <geometry>
                <box size="0.5 0.5 0.5" />
            </geometry>
            <material name="Green">
                <color rgba="0.4 1 0.4 1"/>
            </material>
        </visual>
        <collision>
            <origin xyz="0.0 0.0 0.25" rpy="0 0 0"/>
            <geometry>
                <box size="0.5 0.5 0.5" />
            </geometry>
        </collision>
    </link>
    <joint name="000_011" type="revolute">
       <parent link="000"/>
       <child  link="011"/>
       <origin rpy="0 0 0" xyz="0.0 0.25 0.5" />
     <axis xyz="1 0 0"/>
       <limit effort="0.0" lower="-3.14159" upper="3.14159" velocity="0.0"/>
    </joint>
    <link name="011">
        <inertial>
            <origin xyz="0.0 0.25 0.25" rpy="0 0 0"/>
            <mass value="1" />
            <inertia ixx="100" ixy="0" ixz="0" iyy="100" iyz="0" izz="100" />
        </inertial>
        <visual>
            <origin xyz="0.0 0.25 0.25" rpy="0 0 0"/>
            <geometry>
                <box size="0.5 0.5 0.5" />
            </geometry>
            <material name="Green">
                <color rgba="0.4 1 0.4 1"/>
            </material>
        </visual>
        <collision>
            <origin xyz="0.0 0.25 0.25" rpy="0 0 0"/>
            <geometry>
                <box size="0.5 0.5 0.5" />
            </geometry>
        </collision>
    </link>
    <joint name="011_012" type="continuous">
       <parent link="011"/>
       <child  link="012"/>
       <origin rpy="0 0 0" xyz="-0.25 0.25 0.5" />
     <axis xyz="0 1 0"/>
       <limit effort="0.0" lower="-3.14159" upper="3.14159" velocity="0.0"/>
    </joint>
    <link name="012">
        <inertial>
            <origin xyz="0.25 0.0 0.25" rpy="0 0 0"/>
            <mass value="1" />
            <inertia ixx="100" ixy="0" ixz="0" iyy="100" iyz="0" izz="100" />
        </inertial>
        <visual>
            <origin xyz="0.25 0.0 0.25" rpy="0 0 0"/>
            <geometry>
                <box size="0.5 0.5 0.5" />
            </geometry>
            <material name="Green">
                <color rgba="0.4 1 0.4 1"/>
            </material>
        </visual>
        <collision>
            <origin xyz="0.25 0.0 0.25" rpy="0 0 0"/>
            <geometry>
                <box size="0.5 0.5 0.5" />
            </geometry>
        </collision>
    </link>
    <joint name="011_020" type="revolute">
       <parent link="011"/>
       <child  link="020"/>
       <origin rpy="0 0 0" xyz="0.0 0.5 0.0" />
     <axis xyz="1 0 0"/>
       <limit effort="0.0" lower="-3.14159" upper="3.14159" velocity="0.0"/>
    </joint>
    <link name="020">
        <inertial>
            <origin xyz="0.0 0.25 -0.25" rpy="0 0 0"/>
            <mass value="1" />
            <inertia ixx="100" ixy="0" ixz="0" iyy="100" iyz="0" izz="100" />
        </inertial>
        <visual>
            <origin xyz="0.0 0.25 -0.25" rpy="0 0 0"/>
            <geometry>
                <box size="0.5 0.5 0.5" />
            </geometry>
            <material name="Cyan">
                <color rgba="0 1.0 1.0 1.0"/>
            </material>
        </visual>
        <collision>
            <origin xyz="0.0 0.25 -0.25" rpy="0 0 0"/>
            <geometry>
                <box size="0.5 0.5 0.5" />
            </geometry>
        </collision>
    </link>
    <joint name="020_021" type="revolute">
       <parent link="020"/>
       <child  link="021"/>
       <origin rpy="0 0 0" xyz="0.25 0.25 0.0" />
     <axis xyz="0 1 0"/>
       <limit effort="0.0" lower="-3.14159" upper="3.14159" velocity="0.0"/>
    </joint>
    <link name="021">
        <inertial>
            <origin xyz="-0.25 0.0 0.25" rpy="0 0 0"/>
            <mass value="1" />
            <inertia ixx="100" ixy="0" ixz="0" iyy="100" iyz="0" izz="100" />
        </inertial>
        <visual>
            <origin xyz="-0.25 0.0 0.25" rpy="0 0 0"/>
            <geometry>
                <box size="0.5 0.5 0.5" />
            </geometry>
            <material name="Green">
                <color rgba="0.4 1 0.4 1"/>
            </material>
        </visual>
        <collision>
            <origin xyz="-0.25 0.0 0.25" rpy="0 0 0"/>
            <geometry>
                <box size="0.5 0.5 0.5" />
            </geometry>
        </collision>
    </link>
    <joint name="021_022" type="continuous">
       <parent link="021"/>
       <child  link="022"/>
       <origin rpy="0 0 0" xyz="-0.25 0.0 0.5" />
     <axis xyz="0 1 0"/>
       <limit effort="0.0" lower="-3.14159" upper="3.14159" velocity="0.0"/>
    </joint>
    <link name="022">
        <inertial>
            <origin xyz="0.0 0.0 0.25" rpy="0 0 0"/>
            <mass value="1" />
            <inertia ixx="100" ixy="0" ixz="0" iyy="100" iyz="0" izz="100" />
        </inertial>
        <visual>
            <origin xyz="0.0 0.0 0.25" rpy="0 0 0"/>
            <geometry>
                <box size="0.5 0.5 0.5" />
            </geometry>
            <material name="Green">
                <color rgba="0.4 1 0.4 1"/>
            </material>
        </visual>
        <collision>
            <origin xyz="0.0 0.0 0.25" rpy="0 0 0"/>
            <geometry>
                <box size="0.5 0.5 0.5" />
            </geometry>
        </collision>
    </link>
    <joint name="021_031" type="continuous">
       <parent link="021"/>
       <child  link="031"/>
       <origin rpy="0 0 0" xyz="-0.25 0.25 0.0" />
     <axis xyz="1 0 0"/>
       <limit effort="0.0" lower="-3.14159" upper="3.14159" velocity="0.0"/>
    </joint>
    <link name="031">
        <inertial>
            <origin xyz="0.0 0.25 0.25" rpy="0 0 0"/>
            <mass value="1" />
            <inertia ixx="100" ixy="0" ixz="0" iyy="100" iyz="0" izz="100" />
        </inertial>
        <visual>
            <origin xyz="0.0 0.25 0.25" rpy="0 0 0"/>
            <geometry>
                <box size="0.5 0.5 0.5" />
            </geometry>
            <material name="Green">
                <color rgba="0.4 1 0.4 1"/>
            </material>
        </visual>
        <collision>
            <origin xyz="0.0 0.25 0.25" rpy="0 0 0"/>
            <geometry>
                <box size="0.5 0.5 0.5" />
            </geometry>
        </collision>
    </link>
    <joint name="000_100" type="continuous">
       <parent link="000"/>
       <child  link="100"/>
       <origin rpy="0 0 0" xyz="0.25 -0.25 0.25" />
     <axis xyz="0 0 1"/>
       <limit effort="0.0" lower="-3.14159" upper="3.14159" velocity="0.0"/>
    </joint>
    <link name="100">
        <inertial>
            <origin xyz="0.25 0.25 0.0" rpy="0 0 0"/>
            <mass value="1" />
            <inertia ixx="100" ixy="0" ixz="0" iyy="100" iyz="0" izz="100" />
        </inertial>
        <visual>
            <origin xyz="0.25 0.25 0.0" rpy="0 0 0"/>
            <geometry>
                <box size="0.5 0.5 0.5" />
            </geometry>
            <material name="Green">
                <color rgba="0.4 1 0.4 1"/>
            </material>
        </visual>
        <collision>
            <origin xyz="0.25 0.25 0.0" rpy="0 0 0"/>
            <geometry>
                <box size="0.5 0.5 0.5" />
            </geometry>
        </collision>
    </link>
    <joint name="011_101" type="continuous">
       <parent link="011"/>
       <child  link="101"/>
       <origin rpy="0 0 0" xyz="0.25 0.0 0.25" />
     <axis xyz="0 0 1"/>
       <limit effort="0.0" lower="-3.14159" upper="3.14159" velocity="0.0"/>
    </joint>
    <link name="101">
        <inertial>
            <origin xyz="0.25 -0.25 0.0" rpy="0 0 0"/>
            <mass value="1" />
            <inertia ixx="100" ixy="0" ixz="0" iyy="100" iyz="0" izz="100" />
        </inertial>
        <visual>
            <origin xyz="0.25 -0.25 0.0" rpy="0 0 0"/>
            <geometry>
                <box size="0.5 0.5 0.5" />
            </geometry>
            <material name="Cyan">
                <color rgba="0 1.0 1.0 1.0"/>
            </material>
        </visual>
        <collision>
            <origin xyz="0.25 -0.25 0.0" rpy="0 0 0"/>
            <geometry>
                <box size="0.5 0.5 0.5" />
            </geometry>
        </collision>
    </link>
    <joint name="101_102" type="revolute">
       <parent link="101"/>
       <child  link="102"/>
       <origin rpy="0 0 0" xyz="0.25 -0.5 0.25" />
     <axis xyz="1 0 0"/>
       <limit effort="0.0" lower="-3.14159" upper="3.14159" velocity="0.0"/>
    </joint>
    <link name="102">
        <inertial>
            <origin xyz="0.0 0.25 0.25" rpy="0 0 0"/>
            <mass value="1" />
            <inertia ixx="100" ixy="0" ixz="0" iyy="100" iyz="0" izz="100" />
        </inertial>
        <visual>
            <origin xyz="0.0 0.25 0.25" rpy="0 0 0"/>
            <geometry>
                <box size="0.5 0.5 0.5" />
            </geometry>
            <material name="Cyan">
                <color rgba="0 1.0 1.0 1.0"/>
            </material>
        </visual>
        <collision>
            <origin xyz="0.0 0.25 0.25" rpy="0 0 0"/>
            <geometry>
                <box size="0.5 0.5 0.5" />
            </geometry>
        </collision>
    </link>
    <joint name="102_111" type="revolute">
       <parent link="102"/>
       <child  link="111"/>
       <origin rpy="0 0 0" xyz="0.0 0.5 0.0" />
     <axis xyz="1 0 0"/>
       <limit effort="0.0" lower="-3.14159" upper="3.14159" velocity="0.0"/>
    </joint>
    <link name="111">
        <inertial>
            <origin xyz="0.0 0.25 -0.25" rpy="0 0 0"/>
            <mass value="1" />
            <inertia ixx="100" ixy="0" ixz="0" iyy="100" iyz="0" izz="100" />
        </inertial>
        <visual>
            <origin xyz="0.0 0.25 -0.25" rpy="0 0 0"/>
            <geometry>
                <box size="0.5 0.5 0.5" />
            </geometry>
            <material name="Green">
                <color rgba="0.4 1 0.4 1"/>
            </material>
        </visual>
        <collision>
            <origin xyz="0.0 0.25 -0.25" rpy="0 0 0"/>
            <geometry>
                <box size="0.5 0.5 0.5" />
            </geometry>
        </collision>
    </link>
    <joint name="012_112" type="continuous">
       <parent link="012"/>
       <child  link="112"/>
       <origin rpy="0 0 0" xyz="0.5 -0.25 0.25" />
     <axis xyz="0 0 1"/>
       <limit effort="0.0" lower="-3.14159" upper="3.14159" velocity="0.0"/>
    </joint>
    <link name="112">
        <inertial>
            <origin xyz="0.25 0.25 0.0" rpy="0 0 0"/>
            <mass value="1" />
            <inertia ixx="100" ixy="0" ixz="0" iyy="100" iyz="0" izz="100" />
        </inertial>
        <visual>
            <origin xyz="0.25 0.25 0.0" rpy="0 0 0"/>
            <geometry>
                <box size="0.5 0.5 0.5" />
            </geometry>
            <material name="Cyan">
                <color rgba="0 1.0 1.0 1.0"/>
            </material>
        </visual>
        <collision>
            <origin xyz="0.25 0.25 0.0" rpy="0 0 0"/>
            <geometry>
                <box size="0.5 0.5 0.5" />
            </geometry>
        </collision>
    </link>
    <joint name="021_120" type="continuous">
       <parent link="021"/>
       <child  link="120"/>
       <origin rpy="0 0 0" xyz="0.0 0.0 0.0" />
     <axis xyz="0 1 0"/>
       <limit effort="0.0" lower="-3.14159" upper="3.14159" velocity="0.0"/>
    </joint>
    <link name="120">
        <inertial>
            <origin xyz="0.25 0.0 -0.25" rpy="0 0 0"/>
            <mass value="1" />
            <inertia ixx="100" ixy="0" ixz="0" iyy="100" iyz="0" izz="100" />
        </inertial>
        <visual>
            <origin xyz="0.25 0.0 -0.25" rpy="0 0 0"/>
            <geometry>
                <box size="0.5 0.5 0.5" />
            </geometry>
            <material name="Cyan">
                <color rgba="0 1.0 1.0 1.0"/>
            </material>
        </visual>
        <collision>
            <origin xyz="0.25 0.0 -0.25" rpy="0 0 0"/>
            <geometry>
                <box size="0.5 0.5 0.5" />
            </geometry>
        </collision>
    </link>
    <joint name="120_131" type="revolute">
       <parent link="120"/>
       <child  link="131"/>
       <origin rpy="0 0 0" xyz="0.25 0.25 0.0" />
     <axis xyz="1 0 0"/>
       <limit effort="0.0" lower="-3.14159" upper="3.14159" velocity="0.0"/>
    </joint>
    <link name="131">
        <inertial>
            <origin xyz="0.0 0.25 0.25" rpy="0 0 0"/>
            <mass value="1" />
            <inertia ixx="100" ixy="0" ixz="0" iyy="100" iyz="0" izz="100" />
        </inertial>
        <visual>
            <origin xyz="0.0 0.25 0.25" rpy="0 0 0"/>
            <geometry>
                <box size="0.5 0.5 0.5" />
            </geometry>
            <material name="Cyan">
                <color rgba="0 1.0 1.0 1.0"/>
            </material>
        </visual>
        <collision>
            <origin xyz="0.0 0.25 0.25" rpy="0 0 0"/>
            <geometry>
                <box size="0.5 0.5 0.5" />
            </geometry>
        </collision>
    </link>
    <joint name="101_200" type="revolute">
       <parent link="101"/>
       <child  link="200"/>
       <origin rpy="0 0 0" xyz="0.5 -0.25 -0.25" />
     <axis xyz="0 1 0"/>
       <limit effort="0.0" lower="-3.14159" upper="3.14159" velocity="0.0"/>
    </joint>
    <link name="200">
        <inertial>
            <origin xyz="0.25 0.0 -0.25" rpy="0 0 0"/>
            <mass value="1" />
            <inertia ixx="100" ixy="0" ixz="0" iyy="100" iyz="0" izz="100" />
        </inertial>
        <visual>
            <origin xyz="0.25 0.0 -0.25" rpy="0 0 0"/>
            <geometry>
                <box size="0.5 0.5 0.5" />
            </geometry>
            <material name="Green">
                <color rgba="0.4 1 0.4 1"/>
            </material>
        </visual>
        <collision>
            <origin xyz="0.25 0.0 -0.25" rpy="0 0 0"/>
            <geometry>
                <box size="0.5 0.5 0.5" />
            </geometry>
        </collision>
    </link>
    <joint name="101_211" type="continuous">
       <parent link="101"/>
       <child  link="211"/>
       <origin rpy="0 0 0" xyz="0.5 0.0 0.0" />
     <axis xyz="0 0 1"/>
       <limit effort="0.0" lower="-3.14159" upper="3.14159" velocity="0.0"/>
    </joint>
    <link name="211">
        <inertial>
            <origin xyz="0.25 0.25 0.0" rpy="0 0 0"/>
            <mass value="1" />
            <inertia ixx="100" ixy="0" ixz="0" iyy="100" iyz="0" izz="100" />
        </inertial>
        <visual>
            <origin xyz="0.25 0.25 0.0" rpy="0 0 0"/>
            <geometry>
                <box size="0.5 0.5 0.5" />
            </geometry>
            <material name="Green">
                <color rgba="0.4 1 0.4 1"/>
            </material>
        </visual>
        <collision>
            <origin xyz="0.25 0.25 0.0" rpy="0 0 0"/>
            <geometry>
                <box size="0.5 0.5 0.5" />
            </geometry>
        </collision>
    </link>
    <joint name="211_212" type="continuous">
       <parent link="211"/>
       <child  link="212"/>
       <origin rpy="0 0 0" xyz="0.5 0.25 0.25" />
     <axis xyz="0 1 0"/>
       <limit effort="0.0" lower="-3.14159" upper="3.14159" velocity="0.0"/>
    </joint>
    <link name="212">
        <inertial>
            <origin xyz="-0.25 0.0 0.25" rpy="0 0 0"/>
            <mass value="1" />
            <inertia ixx="100" ixy="0" ixz="0" iyy="100" iyz="0" izz="100" />
        </inertial>
        <visual>
            <origin xyz="-0.25 0.0 0.25" rpy="0 0 0"/>
            <geometry>
                <box size="0.5 0.5 0.5" />
            </geometry>
            <material name="Cyan">
                <color rgba="0 1.0 1.0 1.0"/>
            </material>
        </visual>
        <collision>
            <origin xyz="-0.25 0.0 0.25" rpy="0 0 0"/>
            <geometry>
                <box size="0.5 0.5 0.5" />
            </geometry>
        </collision>
    </link>
    <joint name="120_220" type="continuous">
       <parent link="120"/>
       <child  link="220"/>
       <origin rpy="0 0 0" xyz="0.5 0.25 -0.25" />
     <axis xyz="0 0 1"/>
       <limit effort="0.0" lower="-3.14159" upper="3.14159" velocity="0.0"/>
    </joint>
    <link name="220">
        <inertial>
            <origin xyz="0.25 -0.25 0.0" rpy="0 0 0"/>
            <mass value="1" />
            <inertia ixx="100" ixy="0" ixz="0" iyy="100" iyz="0" izz="100" />
        </inertial>
        <visual>
            <origin xyz="0.25 -0.25 0.0" rpy="0 0 0"/>
            <geometry>
                <box size="0.5 0.5 0.5" />
            </geometry>
            <material name="Cyan">
                <color rgba="0 1.0 1.0 1.0"/>
            </material>
        </visual>
        <collision>
            <origin xyz="0.25 -0.25 0.0" rpy="0 0 0"/>
            <geometry>
                <box size="0.5 0.5 0.5" />
            </geometry>
        </collision>
    </link>
    <joint name="131_230" type="revolute">
       <parent link="131"/>
       <child  link="230"/>
       <origin rpy="0 0 0" xyz="0.25 0.25 0.0" />
     <axis xyz="0 1 0"/>
       <limit effort="0.0" lower="-3.14159" upper="3.14159" velocity="0.0"/>
    </joint>
    <link name="230">
        <inertial>
            <origin xyz="0.25 0.0 -0.25" rpy="0 0 0"/>
            <mass value="1" />
            <inertia ixx="100" ixy="0" ixz="0" iyy="100" iyz="0" izz="100" />
        </inertial>
        <visual>
            <origin xyz="0.25 0.0 -0.25" rpy="0 0 0"/>
            <geometry>
                <box size="0.5 0.5 0.5" />
            </geometry>
            <material name="Cyan">
                <color rgba="0 1.0 1.0 1.0"/>
            </material>
        </visual>
        <collision>
            <origin xyz="0.25 0.0 -0.25" rpy="0 0 0"/>
            <geometry>
                <box size="0.5 0.5 0.5" />
            </geometry>
        </collision>
    </link>
    <joint name="131_232" type="continuous">
       <parent link="131"/>
       <child  link="232"/>
       <origin rpy="0 0 0" xyz="0.25 0.25 0.5" />
     <axis xyz="0 1 0"/>
       <limit effort="0.0" lower="-3.14159" upper="3.14159" velocity="0.0"/>
    </joint>
    <link name="232">
        <inertial>
            <origin xyz="0.25 0.0 0.25" rpy="0 0 0"/>
            <mass value="1" />
            <inertia ixx="100" ixy="0" ixz="0" iyy="100" iyz="0" izz="100" />
        </inertial>
        <visual>
            <origin xyz="0.25 0.0 0.25" rpy="0 0 0"/>
            <geometry>
                <box size="0.5 0.5 0.5" />
            </geometry>
            <material name="Cyan">
                <color rgba="0 1.0 1.0 1.0"/>
            </material>
        </visual>
        <collision>
            <origin xyz="0.25 0.0 0.25" rpy="0 0 0"/>
            <geometry>
                <box size="0.5 0.5 0.5" />
            </geometry>
        </collision>
    </link>
</robot>