<robot name = "robot">
    <link name="0">
        <inertial>
            <origin xyz="0 0 2" rpy="0 0 0"/>
            <mass value="1" />
            <inertia ixx="100" ixy="0" ixz="0" iyy="100" iyz="0" izz="100" />
        </inertial>
        <visual>
            <origin xyz="0 0 2" rpy="0 0 0"/>
            <geometry>
                <box size="0.5906178884501417 0.4394827752588889 0.2099552660585677" />
            </geometry>
            <material name="Green">
                <color rgba="0.4 1 0.4 1"/>
            </material>
        </visual>
        <collision>
            <origin xyz="0 0 2" rpy="0 0 0"/>
            <geometry>
                <box size="0.5906178884501417 0.4394827752588889 0.2099552660585677" />
            </geometry>
        </collision>
    </link>
    <joint name="0_1" type="revolute">
       <parent link="0"/>
       <child  link="1"/>
       <origin rpy="0 0 0" xyz="0 0.21974138762944445 2" />
     <axis xyz="0 0 1"/>
       <limit effort="0.0" lower="-3.14159" upper="3.14159" velocity="0.0"/>
    </joint>
    <link name="1">
        <inertial>
            <origin xyz="0 0.22692147145963543 0" rpy="0 0 0"/>
            <mass value="1" />
            <inertia ixx="100" ixy="0" ixz="0" iyy="100" iyz="0" izz="100" />
        </inertial>
        <visual>
            <origin xyz="0 0.22692147145963543 0" rpy="0 0 0"/>
            <geometry>
                <box size="0.1292582771443733 0.45384294291927085 0.1260355352800179" />
            </geometry>
            <material name="Green">
                <color rgba="0.4 1 0.4 1"/>
            </material>
        </visual>
        <collision>
            <origin xyz="0 0.22692147145963543 0" rpy="0 0 0"/>
            <geometry>
                <box size="0.1292582771443733 0.45384294291927085 0.1260355352800179" />
            </geometry>
        </collision>
    </link>
    <joint name="0_2" type="revolute">
       <parent link="0"/>
       <child  link="2"/>
       <origin rpy="0 0 0" xyz="0 0 1.8950223669707162" />
     <axis xyz="0 1 0"/>
       <limit effort="0.0" lower="-3.14159" upper="3.14159" velocity="0.0"/>
    </joint>
    <link name="2">
        <inertial>
            <origin xyz="0 0 -0.2074658791707819" rpy="0 0 0"/>
            <mass value="1" />
            <inertia ixx="100" ixy="0" ixz="0" iyy="100" iyz="0" izz="100" />
        </inertial>
        <visual>
            <origin xyz="0 0 -0.2074658791707819" rpy="0 0 0"/>
            <geometry>
                <box size="0.5353630535978452 0.5431646785360508 0.4149317583415638" />
            </geometry>
            <material name="Cyan">
                <color rgba="0 1.0 1.0 1.0"/>
            </material>
        </visual>
        <collision>
            <origin xyz="0 0 -0.2074658791707819" rpy="0 0 0"/>
            <geometry>
                <box size="0.5353630535978452 0.5431646785360508 0.4149317583415638" />
            </geometry>
        </collision>
    </link>
    <joint name="1_11" type="revolute">
       <parent link="1"/>
       <child  link="11"/>
       <origin rpy="0 0 0" xyz="0.06462913857218665 0.45384294291927085 0" />
     <axis xyz="0 0 1"/>
       <limit effort="0.0" lower="-3.14159" upper="3.14159" velocity="0.0"/>
    </joint>
    <link name="11">
        <inertial>
            <origin xyz="0.08328849889956545 0.2869991923239626 0" rpy="0 0 0"/>
            <mass value="1" />
            <inertia ixx="100" ixy="0" ixz="0" iyy="100" iyz="0" izz="100" />
        </inertial>
        <visual>
            <origin xyz="0.08328849889956545 0.2869991923239626 0" rpy="0 0 0"/>
            <geometry>
                <box size="0.1665769977991309 0.5739983846479252 0.2285286189897104" />
            </geometry>
            <material name="Cyan">
                <color rgba="0 1.0 1.0 1.0"/>
            </material>
        </visual>
        <collision>
            <origin xyz="0.08328849889956545 0.2869991923239626 0" rpy="0 0 0"/>
            <geometry>
                <box size="0.1665769977991309 0.5739983846479252 0.2285286189897104" />
            </geometry>
        </collision>
    </link>
    <joint name="2_21" type="revolute">
       <parent link="2"/>
       <child  link="21"/>
       <origin rpy="0 0 0" xyz="-0.2676815267989226 0 -0.4149317583415638" />
     <axis xyz="0 1 0"/>
       <limit effort="0.0" lower="-3.14159" upper="3.14159" velocity="0.0"/>
    </joint>
    <link name="21">
        <inertial>
            <origin xyz="-0.05403946895288782 0 -0.17814509907291398" rpy="0 0 0"/>
            <mass value="1" />
            <inertia ixx="100" ixy="0" ixz="0" iyy="100" iyz="0" izz="100" />
        </inertial>
        <visual>
            <origin xyz="-0.05403946895288782 0 -0.17814509907291398" rpy="0 0 0"/>
            <geometry>
                <box size="0.10807893790577563 0.3981031282460137 0.35629019814582796" />
            </geometry>
            <material name="Cyan">
                <color rgba="0 1.0 1.0 1.0"/>
            </material>
        </visual>
        <collision>
            <origin xyz="-0.05403946895288782 0 -0.17814509907291398" rpy="0 0 0"/>
            <geometry>
                <box size="0.10807893790577563 0.3981031282460137 0.35629019814582796" />
            </geometry>
        </collision>
    </link>
    <joint name="2_22" type="revolute">
       <parent link="2"/>
       <child  link="22"/>
       <origin rpy="0 0 0" xyz="-0.2676815267989226 0 -0.4149317583415638" />
     <axis xyz="0 1 0"/>
       <limit effort="0.0" lower="-3.14159" upper="3.14159" velocity="0.0"/>
    </joint>
    <link name="22">
        <inertial>
            <origin xyz="-0.294695906803316 0 -0.08425241330311477" rpy="0 0 0"/>
            <mass value="1" />
            <inertia ixx="100" ixy="0" ixz="0" iyy="100" iyz="0" izz="100" />
        </inertial>
        <visual>
            <origin xyz="-0.294695906803316 0 -0.08425241330311477" rpy="0 0 0"/>
            <geometry>
                <box size="0.589391813606632 0.18122344946513538 0.16850482660622954" />
            </geometry>
            <material name="Green">
                <color rgba="0.4 1 0.4 1"/>
            </material>
        </visual>
        <collision>
            <origin xyz="-0.294695906803316 0 -0.08425241330311477" rpy="0 0 0"/>
            <geometry>
                <box size="0.589391813606632 0.18122344946513538 0.16850482660622954" />
            </geometry>
        </collision>
    </link>
    <joint name="11_111" type="revolute">
       <parent link="11"/>
       <child  link="111"/>
       <origin rpy="0 0 0" xyz="0.1665769977991309 0 0" />
     <axis xyz="0 1 0"/>
       <limit effort="0.0" lower="-3.14159" upper="3.14159" velocity="0.0"/>
    </joint>
    <link name="111">
        <inertial>
            <origin xyz="0.17699975382305028 0 0.22242817060295195" rpy="0 0 0"/>
            <mass value="1" />
            <inertia ixx="100" ixy="0" ixz="0" iyy="100" iyz="0" izz="100" />
        </inertial>
        <visual>
            <origin xyz="0.17699975382305028 0 0.22242817060295195" rpy="0 0 0"/>
            <geometry>
                <box size="0.35399950764610055 0.11125922549572545 0.4448563412059039" />
            </geometry>
            <material name="Cyan">
                <color rgba="0 1.0 1.0 1.0"/>
            </material>
        </visual>
        <collision>
            <origin xyz="0.17699975382305028 0 0.22242817060295195" rpy="0 0 0"/>
            <geometry>
                <box size="0.35399950764610055 0.11125922549572545 0.4448563412059039" />
            </geometry>
        </collision>
    </link>
    <joint name="11_112" type="revolute">
       <parent link="11"/>
       <child  link="112"/>
       <origin rpy="0 0 0" xyz="0.1665769977991309 0 0" />
     <axis xyz="0 1 0"/>
       <limit effort="0.0" lower="-3.14159" upper="3.14159" velocity="0.0"/>
    </joint>
    <link name="112">
        <inertial>
            <origin xyz="0.21283527411912972 0 0.2922091231854354" rpy="0 0 0"/>
            <mass value="1" />
            <inertia ixx="100" ixy="0" ixz="0" iyy="100" iyz="0" izz="100" />
        </inertial>
        <visual>
            <origin xyz="0.21283527411912972 0 0.2922091231854354" rpy="0 0 0"/>
            <geometry>
                <box size="0.42567054823825945 0.17645485592087498 0.5844182463708708" />
            </geometry>
            <material name="Cyan">
                <color rgba="0 1.0 1.0 1.0"/>
            </material>
        </visual>
        <collision>
            <origin xyz="0.21283527411912972 0 0.2922091231854354" rpy="0 0 0"/>
            <geometry>
                <box size="0.42567054823825945 0.17645485592087498 0.5844182463708708" />
            </geometry>
        </collision>
    </link>
    <joint name="21_211" type="revolute">
       <parent link="21"/>
       <child  link="211"/>
       <origin rpy="0 0 0" xyz="-0.10807893790577563 0 0" />
     <axis xyz="0 0 1"/>
       <limit effort="0.0" lower="-3.14159" upper="3.14159" velocity="0.0"/>
    </joint>
    <link name="211">
        <inertial>
            <origin xyz="-0.24090317782825676 -0.08030728070546773 0" rpy="0 0 0"/>
            <mass value="1" />
            <inertia ixx="100" ixy="0" ixz="0" iyy="100" iyz="0" izz="100" />
        </inertial>
        <visual>
            <origin xyz="-0.24090317782825676 -0.08030728070546773 0" rpy="0 0 0"/>
            <geometry>
                <box size="0.48180635565651353 0.16061456141093547 0.328399289625551" />
            </geometry>
            <material name="Green">
                <color rgba="0.4 1 0.4 1"/>
            </material>
        </visual>
        <collision>
            <origin xyz="-0.24090317782825676 -0.08030728070546773 0" rpy="0 0 0"/>
            <geometry>
                <box size="0.48180635565651353 0.16061456141093547 0.328399289625551" />
            </geometry>
        </collision>
    </link>
    <joint name="21_212" type="revolute">
       <parent link="21"/>
       <child  link="212"/>
       <origin rpy="0 0 0" xyz="-0.10807893790577563 0 0" />
     <axis xyz="0 1 0"/>
       <limit effort="0.0" lower="-3.14159" upper="3.14159" velocity="0.0"/>
    </joint>
    <link name="212">
        <inertial>
            <origin xyz="-0.15490268593727413 0 -0.28401904453040955" rpy="0 0 0"/>
            <mass value="1" />
            <inertia ixx="100" ixy="0" ixz="0" iyy="100" iyz="0" izz="100" />
        </inertial>
        <visual>
            <origin xyz="-0.15490268593727413 0 -0.28401904453040955" rpy="0 0 0"/>
            <geometry>
                <box size="0.30980537187454826 0.2922575772193098 0.5680380890608191" />
            </geometry>
            <material name="Cyan">
                <color rgba="0 1.0 1.0 1.0"/>
            </material>
        </visual>
        <collision>
            <origin xyz="-0.15490268593727413 0 -0.28401904453040955" rpy="0 0 0"/>
            <geometry>
                <box size="0.30980537187454826 0.2922575772193098 0.5680380890608191" />
            </geometry>
        </collision>
    </link>
    <joint name="22_221" type="revolute">
       <parent link="22"/>
       <child  link="221"/>
       <origin rpy="0 0 0" xyz="-0.589391813606632 0 0" />
     <axis xyz="0 1 0"/>
       <limit effort="0.0" lower="-3.14159" upper="3.14159" velocity="0.0"/>
    </joint>
    <link name="221">
        <inertial>
            <origin xyz="-0.12046597873904431 0 0.1420794809920481" rpy="0 0 0"/>
            <mass value="1" />
            <inertia ixx="100" ixy="0" ixz="0" iyy="100" iyz="0" izz="100" />
        </inertial>
        <visual>
            <origin xyz="-0.12046597873904431 0 0.1420794809920481" rpy="0 0 0"/>
            <geometry>
                <box size="0.24093195747808863 0.1598217290761403 0.2841589619840962" />
            </geometry>
            <material name="Green">
                <color rgba="0.4 1 0.4 1"/>
            </material>
        </visual>
        <collision>
            <origin xyz="-0.12046597873904431 0 0.1420794809920481" rpy="0 0 0"/>
            <geometry>
                <box size="0.24093195747808863 0.1598217290761403 0.2841589619840962" />
            </geometry>
        </collision>
    </link>
</robot>