<robot name = "robot">
    <link name="000">
        <inertial>
            <origin xyz="0.0 0.0 0.25" rpy="0 0 0"/>
            <mass value="1" />
            <inertia ixx="100" ixy="0" ixz="0" iyy="100" iyz="0" izz="100" />
        </inertial>
        <visual>
            <origin xyz="0.0 0.0 0.25" rpy="0 0 0"/>
            <geometry>
                <box size="1.0 0.5 0.5" />
            </geometry>
            <material name="Green">
                <color rgba="0.4 1 0.4 1"/>
            </material>
        </visual>
        <collision>
            <origin xyz="0.0 0.0 0.25" rpy="0 0 0"/>
            <geometry>
                <box size="1.0 0.5 0.5" />
            </geometry>
        </collision>
    </link>
    <joint name="000_010" type="continuous">
       <parent link="000"/>
       <child  link="010"/>
       <origin rpy="0 0 0" xyz="0.0 0.25 0.0" />
     <axis xyz="1 0 0"/>
       <limit effort="0.0" lower="-3.14159" upper="3.14159" velocity="0.0"/>
    </joint>
    <link name="010">
        <inertial>
            <origin xyz="0.0 0.25 0.25" rpy="0 0 0"/>
            <mass value="1" />
            <inertia ixx="100" ixy="0" ixz="0" iyy="100" iyz="0" izz="100" />
        </inertial>
        <visual>
            <origin xyz="0.0 0.25 0.25" rpy="0 0 0"/>
            <geometry>
                <box size="1.0 0.5 0.5" />
            </geometry>
            <material name="Green">
                <color rgba="0.4 1 0.4 1"/>
            </material>
        </visual>
        <collision>
            <origin xyz="0.0 0.25 0.25" rpy="0 0 0"/>
            <geometry>
                <box size="1.0 0.5 0.5" />
            </geometry>
        </collision>
    </link>
    <joint name="000_011" type="continuous">
       <parent link="000"/>
       <child  link="011"/>
       <origin rpy="0 0 0" xyz="0.0 0.25 0.5" />
     <axis xyz="1 0 0"/>
       <limit effort="0.0" lower="-3.14159" upper="3.14159" velocity="0.0"/>
    </joint>
    <link name="011">
        <inertial>
            <origin xyz="0.0 0.25 0.25" rpy="0 0 0"/>
            <mass value="1" />
            <inertia ixx="100" ixy="0" ixz="0" iyy="100" iyz="0" izz="100" />
        </inertial>
        <visual>
            <origin xyz="0.0 0.25 0.25" rpy="0 0 0"/>
            <geometry>
                <box size="1.0 0.5 0.5" />
            </geometry>
            <material name="Green">
                <color rgba="0.4 1 0.4 1"/>
            </material>
        </visual>
        <collision>
            <origin xyz="0.0 0.25 0.25" rpy="0 0 0"/>
            <geometry>
                <box size="1.0 0.5 0.5" />
            </geometry>
        </collision>
    </link>
    <joint name="010_020" type="continuous">
       <parent link="010"/>
       <child  link="020"/>
       <origin rpy="0 0 0" xyz="-0.5 0.5 0.25" />
     <axis xyz="0 0 1"/>
       <limit effort="0.0" lower="-3.14159" upper="3.14159" velocity="0.0"/>
    </joint>
    <link name="020">
        <inertial>
            <origin xyz="0.5 0.25 0.0" rpy="0 0 0"/>
            <mass value="1" />
            <inertia ixx="100" ixy="0" ixz="0" iyy="100" iyz="0" izz="100" />
        </inertial>
        <visual>
            <origin xyz="0.5 0.25 0.0" rpy="0 0 0"/>
            <geometry>
                <box size="1.0 0.5 0.5" />
            </geometry>
            <material name="Green">
                <color rgba="0.4 1 0.4 1"/>
            </material>
        </visual>
        <collision>
            <origin xyz="0.5 0.25 0.0" rpy="0 0 0"/>
            <geometry>
                <box size="1.0 0.5 0.5" />
            </geometry>
        </collision>
    </link>
    <joint name="011_021" type="continuous">
       <parent link="011"/>
       <child  link="021"/>
       <origin rpy="0 0 0" xyz="0.0 0.5 0.0" />
     <axis xyz="1 0 0"/>
       <limit effort="0.0" lower="-3.14159" upper="3.14159" velocity="0.0"/>
    </joint>
    <link name="021">
        <inertial>
            <origin xyz="0.0 0.25 0.25" rpy="0 0 0"/>
            <mass value="1" />
            <inertia ixx="100" ixy="0" ixz="0" iyy="100" iyz="0" izz="100" />
        </inertial>
        <visual>
            <origin xyz="0.0 0.25 0.25" rpy="0 0 0"/>
            <geometry>
                <box size="1.0 0.5 0.5" />
            </geometry>
            <material name="Green">
                <color rgba="0.4 1 0.4 1"/>
            </material>
        </visual>
        <collision>
            <origin xyz="0.0 0.25 0.25" rpy="0 0 0"/>
            <geometry>
                <box size="1.0 0.5 0.5" />
            </geometry>
        </collision>
    </link>
    <joint name="021_030" type="revolute">
       <parent link="021"/>
       <child  link="030"/>
       <origin rpy="0 0 0" xyz="0.0 0.5 0.0" />
     <axis xyz="1 0 0"/>
       <limit effort="0.0" lower="-3.14159" upper="3.14159" velocity="0.0"/>
    </joint>
    <link name="030">
        <inertial>
            <origin xyz="0.0 0.25 -0.25" rpy="0 0 0"/>
            <mass value="1" />
            <inertia ixx="100" ixy="0" ixz="0" iyy="100" iyz="0" izz="100" />
        </inertial>
        <visual>
            <origin xyz="0.0 0.25 -0.25" rpy="0 0 0"/>
            <geometry>
                <box size="1.0 0.5 0.5" />
            </geometry>
            <material name="Cyan">
                <color rgba="0 1.0 1.0 1.0"/>
            </material>
        </visual>
        <collision>
            <origin xyz="0.0 0.25 -0.25" rpy="0 0 0"/>
            <geometry>
                <box size="1.0 0.5 0.5" />
            </geometry>
        </collision>
    </link>
    <joint name="011_101" type="revolute">
       <parent link="011"/>
       <child  link="101"/>
       <origin rpy="0 0 0" xyz="0.5 0.0 0.25" />
     <axis xyz="0 0 1"/>
       <limit effort="0.0" lower="-3.14159" upper="3.14159" velocity="0.0"/>
    </joint>
    <link name="101">
        <inertial>
            <origin xyz="0.5 -0.25 0.0" rpy="0 0 0"/>
            <mass value="1" />
            <inertia ixx="100" ixy="0" ixz="0" iyy="100" iyz="0" izz="100" />
        </inertial>
        <visual>
            <origin xyz="0.5 -0.25 0.0" rpy="0 0 0"/>
            <geometry>
                <box size="1.0 0.5 0.5" />
            </geometry>
            <material name="Green">
                <color rgba="0.4 1 0.4 1"/>
            </material>
        </visual>
        <collision>
            <origin xyz="0.5 -0.25 0.0" rpy="0 0 0"/>
            <geometry>
                <box size="1.0 0.5 0.5" />
            </geometry>
        </collision>
    </link>
    <joint name="101_110" type="continuous">
       <parent link="101"/>
       <child  link="110"/>
       <origin rpy="0 0 0" xyz="0.5 0.0 -0.25" />
     <axis xyz="1 0 0"/>
       <limit effort="0.0" lower="-3.14159" upper="3.14159" velocity="0.0"/>
    </joint>
    <link name="110">
        <inertial>
            <origin xyz="0.0 0.25 -0.25" rpy="0 0 0"/>
            <mass value="1" />
            <inertia ixx="100" ixy="0" ixz="0" iyy="100" iyz="0" izz="100" />
        </inertial>
        <visual>
            <origin xyz="0.0 0.25 -0.25" rpy="0 0 0"/>
            <geometry>
                <box size="1.0 0.5 0.5" />
            </geometry>
            <material name="Green">
                <color rgba="0.4 1 0.4 1"/>
            </material>
        </visual>
        <collision>
            <origin xyz="0.0 0.25 -0.25" rpy="0 0 0"/>
            <geometry>
                <box size="1.0 0.5 0.5" />
            </geometry>
        </collision>
    </link>
    <joint name="021_120" type="continuous">
       <parent link="021"/>
       <child  link="120"/>
       <origin rpy="0 0 0" xyz="0.5 0.25 0.0" />
     <axis xyz="0 1 0"/>
       <limit effort="0.0" lower="-3.14159" upper="3.14159" velocity="0.0"/>
    </joint>
    <link name="120">
        <inertial>
            <origin xyz="0.5 0.0 -0.25" rpy="0 0 0"/>
            <mass value="1" />
            <inertia ixx="100" ixy="0" ixz="0" iyy="100" iyz="0" izz="100" />
        </inertial>
        <visual>
            <origin xyz="0.5 0.0 -0.25" rpy="0 0 0"/>
            <geometry>
                <box size="1.0 0.5 0.5" />
            </geometry>
            <material name="Cyan">
                <color rgba="0 1.0 1.0 1.0"/>
            </material>
        </visual>
        <collision>
            <origin xyz="0.5 0.0 -0.25" rpy="0 0 0"/>
            <geometry>
                <box size="1.0 0.5 0.5" />
            </geometry>
        </collision>
    </link>
    <joint name="011_121" type="revolute">
       <parent link="011"/>
       <child  link="121"/>
       <origin rpy="0 0 0" xyz="0.5 0.5 0.25" />
     <axis xyz="0 0 1"/>
       <limit effort="0.0" lower="-3.14159" upper="3.14159" velocity="0.0"/>
    </joint>
    <link name="121">
        <inertial>
            <origin xyz="0.5 0.25 0.0" rpy="0 0 0"/>
            <mass value="1" />
            <inertia ixx="100" ixy="0" ixz="0" iyy="100" iyz="0" izz="100" />
        </inertial>
        <visual>
            <origin xyz="0.5 0.25 0.0" rpy="0 0 0"/>
            <geometry>
                <box size="1.0 0.5 0.5" />
            </geometry>
            <material name="Green">
                <color rgba="0.4 1 0.4 1"/>
            </material>
        </visual>
        <collision>
            <origin xyz="0.5 0.25 0.0" rpy="0 0 0"/>
            <geometry>
                <box size="1.0 0.5 0.5" />
            </geometry>
        </collision>
    </link>
    <joint name="121_131" type="continuous">
       <parent link="121"/>
       <child  link="131"/>
       <origin rpy="0 0 0" xyz="0.0 0.5 0.0" />
     <axis xyz="0 0 1"/>
       <limit effort="0.0" lower="-3.14159" upper="3.14159" velocity="0.0"/>
    </joint>
    <link name="131">
        <inertial>
            <origin xyz="0.5 0.25 0.0" rpy="0 0 0"/>
            <mass value="1" />
            <inertia ixx="100" ixy="0" ixz="0" iyy="100" iyz="0" izz="100" />
        </inertial>
        <visual>
            <origin xyz="0.5 0.25 0.0" rpy="0 0 0"/>
            <geometry>
                <box size="1.0 0.5 0.5" />
            </geometry>
            <material name="Green">
                <color rgba="0.4 1 0.4 1"/>
            </material>
        </visual>
        <collision>
            <origin xyz="0.5 0.25 0.0" rpy="0 0 0"/>
            <geometry>
                <box size="1.0 0.5 0.5" />
            </geometry>
        </collision>
    </link>
    <joint name="101_202" type="revolute">
       <parent link="101"/>
       <child  link="202"/>
       <origin rpy="0 0 0" xyz="1.0 -0.25 0.25" />
     <axis xyz="0 1 0"/>
       <limit effort="0.0" lower="-3.14159" upper="3.14159" velocity="0.0"/>
    </joint>
    <link name="202">
        <inertial>
            <origin xyz="0.5 0.0 0.25" rpy="0 0 0"/>
            <mass value="1" />
            <inertia ixx="100" ixy="0" ixz="0" iyy="100" iyz="0" izz="100" />
        </inertial>
        <visual>
            <origin xyz="0.5 0.0 0.25" rpy="0 0 0"/>
            <geometry>
                <box size="1.0 0.5 0.5" />
            </geometry>
            <material name="Green">
                <color rgba="0.4 1 0.4 1"/>
            </material>
        </visual>
        <collision>
            <origin xyz="0.5 0.0 0.25" rpy="0 0 0"/>
            <geometry>
                <box size="1.0 0.5 0.5" />
            </geometry>
        </collision>
    </link>
    <joint name="120_210" type="continuous">
       <parent link="120"/>
       <child  link="210"/>
       <origin rpy="0 0 0" xyz="1.0 -0.25 -0.25" />
     <axis xyz="0 0 1"/>
       <limit effort="0.0" lower="-3.14159" upper="3.14159" velocity="0.0"/>
    </joint>
    <link name="210">
        <inertial>
            <origin xyz="0.5 -0.25 0.0" rpy="0 0 0"/>
            <mass value="1" />
            <inertia ixx="100" ixy="0" ixz="0" iyy="100" iyz="0" izz="100" />
        </inertial>
        <visual>
            <origin xyz="0.5 -0.25 0.0" rpy="0 0 0"/>
            <geometry>
                <box size="1.0 0.5 0.5" />
            </geometry>
            <material name="Green">
                <color rgba="0.4 1 0.4 1"/>
            </material>
        </visual>
        <collision>
            <origin xyz="0.5 -0.25 0.0" rpy="0 0 0"/>
            <geometry>
                <box size="1.0 0.5 0.5" />
            </geometry>
        </collision>
    </link>
    <joint name="210_221" type="revolute">
       <parent link="210"/>
       <child  link="221"/>
       <origin rpy="0 0 0" xyz="0.5 0.0 0.25" />
     <axis xyz="1 0 0"/>
       <limit effort="0.0" lower="-3.14159" upper="3.14159" velocity="0.0"/>
    </joint>
    <link name="221">
        <inertial>
            <origin xyz="0.0 0.25 0.25" rpy="0 0 0"/>
            <mass value="1" />
            <inertia ixx="100" ixy="0" ixz="0" iyy="100" iyz="0" izz="100" />
        </inertial>
        <visual>
            <origin xyz="0.0 0.25 0.25" rpy="0 0 0"/>
            <geometry>
                <box size="1.0 0.5 0.5" />
            </geometry>
            <material name="Cyan">
                <color rgba="0 1.0 1.0 1.0"/>
            </material>
        </visual>
        <collision>
            <origin xyz="0.0 0.25 0.25" rpy="0 0 0"/>
            <geometry>
                <box size="1.0 0.5 0.5" />
            </geometry>
        </collision>
    </link>
</robot>